Workbook

Sheet Cover
B2: Netflix
B3: Discounted Cash Flow
B4: Ticker: | C4: NFLX

Sheet Outputs
A1: Netflix
B3: Model Set to: | C3: 2 | E3: Date | F3: 46024 | H3: (All figures are in thousands uless stated otherwise)
B5: Main Outputs | H5: Selected Inputs
B7: =Model!K104 -> 4.0866567e+08 | C7: Enterprise Value | D7: Equity Value | E7: Equity Per Share | H7: Terminal Growth Rate | J7: =Model!G22 -> 0.025
B8: Best Case | C8: 4.9182334e+08 | D8: 4.8639418e+08 | E8: 111.97273 | H8: WACC | J8: =Model!G17 -> 0.10654015
B9: Base Case | C9: 4.0323652e+08 | D9: 4.0323652e+08 | E9: 92.829013 | H9: Shares Outstanding | J9: 4.3B
B10: Worst Case | C10: 3.4332128e+08 | D10: 3.3789212e+08 | E10: 77.786091 | H10: Stock Price | J10: 85.76
H11: Date | J11: 46024
B14: Enterprise Value Bridge | H14: WACC x TGV
I17: =Model!D21 -> 0.02 | J17: =Model!D22 -> 0.025 | K17: =Model!D23 -> 0.03
H18: =Model!D16 -> 0.11186715 | I18: 77.8 | J18: 80.59 | K18: 83.74
H19: =Model!D17 -> 0.10654015 | I19: 89.25 | J19: 92.8 | K19: 96.87
H20: =Model!D18 -> 0.10121314 | I20: 102.23 | J20: 106.78 | K20: 112
B37: Revenue x EBIT

Sheet Model
A1: Netflix
A3: X | B3: ASSUMPTIONS
G4: 1 | H4: =G4+1 -> 2 | I4: =H4+1 -> 3 | J4: =I4+1 -> 4 | K4: =J4+1 -> 5
B5: Revenue Growth | D5: =Statements!F4 -> 2023 | E5: =Statements!G4 -> 2024 | F5: =E5+1 -> 2025 | G5: =F5+1 -> 2026 | H5: =G5+1 -> 2027 | I5: =H5+1 -> 2028 | J5: =I5+1 -> 2029 | K5: =J5+1 -> 2030
B6: Worst (95%) | D6: 0 | E6: =E7*0.95 -> 0.14867424 | F6: =F7*0.95 -> 0.15058515 | G6: =G7*0.95 -> 0.14108515 | H6: =H7*0.95 -> 0.13158515 | I6: =I7*0.95 -> 0.12208515 | J6: =J7*0.95 -> 0.11258515 | K6: =K7*0.95 -> 0.10308515
B7: Base | D7: 0 | E7: =(Statements!G5-Statements!F5)/Statements!F5 -> 0.1564992 | F7: =(Statements!H5-Statements!G5)/Statements!G5 -> 0.15851069 | G7: =F7-1% -> 0.14851069 | H7: =G7-1% -> 0.13851069 | I7: =H7-1% -> 0.12851069 | J7: =I7-1% -> 0.11851069 | K7: =J7-1% -> 0.10851069
B8: Best (105%) | D8: 0 | E8: =E7*1.05 -> 0.16432416 | F8: =F7*1.05 -> 0.16643622 | G8: =G7*1.05 -> 0.15593622 | H8: =H7*1.05 -> 0.14543622 | I8: =I7*1.05 -> 0.13493622 | J8: =J7*1.05 -> 0.12443622 | K8: =K7*1.05 -> 0.11393622
B10: Operating Margin | D10: =D5 -> 2023 | E10: =E5 -> 2024 | F10: =F5 -> 2025 | G10: =G5 -> 2026 | H10: =H5 -> 2027 | I10: =I5 -> 2028 | J10: =J5 -> 2029 | K10: =K5 -> 2030
B11: Worst (95%) | D11: 0 | E11: 0 | F11: =F12*0.95 -> 0.28019969 | G11: =$F11 + ( $K11 - $F11 )*(1/5) -> 0.28515976 | H11: =$F11 + ( $K11 - $F11 )*(2/5) -> 0.29011982 | I11: =$F11 + ( $K11 - $F11 )*(3/5) -> 0.29507988 | J11: =$F11 + ( $K11 - $F11 )*(4/5) -> 0.30003994 | K11: 0.305
B12: Base | D12: =Statements!F10/Statements!F5 -> 0.20620768 | E12: =Statements!G10/Statements!G5 -> 0.26711169 | F12: =Statements!H10/Statements!H5 -> 0.29494705 | G12: =$F$12 + ( $K$12 - $F$12 )*(1/5) -> 0.30395764 | H12: =$F$12 + ( $K$12 - $F$12 )*(2/5) -> 0.31296823 | I12: =$F$12 + ( $K$12 - $F$12 )*(3/5) -> 0.32197882 | J12: =$F$12 + ( $K$12 - $F$12 )*(4/5) -> 0.33098941 | K12: 0.34
B13: Best (105%) | D13: 0 | E13: 0 | F13: =F12*1.05 -> 0.3096944 | G13: =$F13 + ( $K13 - $F13 )*(1/5) -> 0.32175552 | H13: =$F13 + ( $K13 - $F13 )*(2/5) -> 0.33381664 | I13: =$F13 + ( $K13 - $F13 )*(3/5) -> 0.34587776 | J13: =$F13 + ( $K13 - $F13 )*(4/5) -> 0.35793888 | K13: 0.37
B15: WACC
B16: Worst (95%) | D16: =D17*1.05 -> 0.11186715
B17: Base | D17: =C92 -> 0.10654015 | F17: Currently in use | G17: =CHOOSE(C29,D16,D17,D18) -> 0.10654015
B18: Best (105%) | D18: =D17*0.95 -> 0.10121314
B20: TGV
B21: Worst (95%) | D21: 0.02
B22: Base | D22: 0.025 | F22: Currently in use | G22: =CHOOSE(C29,D21,D22,D23) -> 0.025
B23: Best (105%) | D23: 0.03
B25: Effective Tax Rate: | C25: 0.13
A27: X | B27: REVENUE FORECAST
B29: Swtich: | C29: =Outputs!C3 -> 2
D31: =Statements!F4 -> 2023 | E31: =Statements!G4 -> 2024 | F31: =Statements!H4 -> 2025 | G31: =G5 -> 2026 | H31: =H5 -> 2027 | I31: =I5 -> 2028 | J31: =J5 -> 2029 | K31: =K5 -> 2030
B33: Revenue Growth | D33: =CHOOSE($C$29,D6,D7,D8) -> 0 | E33: =CHOOSE($C$29,E6,E7,E8) -> 0.1564992 | F33: =CHOOSE($C$29,F6,F7,F8) -> 0.15851069 | G33: =CHOOSE($C$29,G6,G7,G8) -> 0.14851069 | H33: =CHOOSE($C$29,H6,H7,H8) -> 0.13851069 | I33: =CHOOSE($C$29,I6,I7,I8) -> 0.12851069 | J33: =CHOOSE($C$29,J6,J7,J8) -> 0.11851069 | K33: =CHOOSE($C$29,K6,K7,K8) -> 0.10851069
B34: Revenue | D34: =Statements!F5 -> 33723297 | E34: =Statements!G5 -> 39000966 | F34: =Statements!H5 -> 45183036 | G34: =F34*(1+G33) -> 51893200 | H34: =G34*(1+H33) -> 59080963 | I34: =H34*(1+I33) -> 66673498 | J34: =I34*(1+J33) -> 74575020 | K34: =J34*(1+K33) -> 82667207
A36: X | B36: EBIT FORECAST
D38: =D31 -> 2023 | E38: =E31 -> 2024 | F38: =F31 -> 2025 | G38: =G31 -> 2026 | H38: =H31 -> 2027 | I38: =I31 -> 2028 | J38: =J31 -> 2029 | K38: =K31 -> 2030
B40: Operating Margin | D40: =CHOOSE($C$29,D11,D12,D13) -> 0.20620768 | E40: =CHOOSE($C$29,E11,E12,E13) -> 0.26711169 | F40: =CHOOSE($C$29,F11,F12,F13) -> 0.29494705 | G40: =CHOOSE($C$29,G11,G12,G13) -> 0.30395764 | H40: =CHOOSE($C$29,H11,H12,H13) -> 0.31296823 | I40: =CHOOSE($C$29,I11,I12,I13) -> 0.32197882 | J40: =CHOOSE($C$29,J11,J12,J13) -> 0.33098941 | K40: =CHOOSE($C$29,K11,K12,K13) -> 0.34
B41: EBIT | D41: =Statements!F10 -> 6954003 | E41: =Statements!G10 -> 10417614 | F41: =Statements!H10 -> 13326603 | G41: =G40*G34 -> 15773334 | H41: =H40*H34 -> 18490464 | I41: =I40*I34 -> 21467454 | J41: =J40*J34 -> 24683542 | K41: =K40*K34 -> 28106850
A43: X | B43: D&A FORECAST
D45: =D31 -> 2023 | E45: =E31 -> 2024 | F45: =F31 -> 2025 | G45: =G31 -> 2026 | H45: =H31 -> 2027 | I45: =I31 -> 2028 | J45: =J31 -> 2029 | K45: =K31 -> 2030
B47: D&A (% Revenue) | D47: =D48/D34 -> 0.43158248 | E47: =E48/E34 -> 0.40077036 | F47: =F48/F34 -> 0.3708373 | G47: =$F47 + ( $K47 - $F47 )*(1/5) -> 0.36566984 | H47: =$F47 + ( $K47 - $F47 )*(2/5) -> 0.36050238 | I47: =$F47 + ( $K47 - $F47 )*(3/5) -> 0.35533492 | J47: =$F47 + ( $K47 - $F47 )*(4/5) -> 0.35016746 | K47: 0.345
B48: D&A | D48: =Statements!F27+Statements!F29 -> 14554384 | E48: =Statements!G27+Statements!G29 -> 15630431 | F48: =Statements!H27+Statements!H29 -> 16755555 | G48: =G47*G34 -> 18975778 | H48: =H47*H34 -> 21298828 | I48: =I47*I34 -> 23691422 | J48: =J47*J34 -> 26113745 | K48: =K47*K34 -> 28520186
A50: X | B50: CAPEX FORECAST
D52: =D38 -> 2023 | E52: =E38 -> 2024 | F52: =F38 -> 2025 | G52: =G38 -> 2026 | H52: =H38 -> 2027 | I52: =I38 -> 2028 | J52: =J38 -> 2029 | K52: =K38 -> 2030
B54: CapEx (% Revenue) | D54: =-Statements!F43/Statements!F5 -> 0.010335644 | E54: =-Statements!G43/Statements!G5 -> 0.011269926 | F54: =-Statements!H43/Statements!H5 -> 0.015231823 | G54: 0.014 | H54: 0.014 | I54: 0.014 | J54: 0.014 | K54: 0.014
B55: CapEx | D55: =Statements!F43 -> -348552 | E55: =Statements!G43 -> -439538 | F55: =Statements!H43 -> -688220 | G55: =G54*-G34 -> -726504.8 | H55: =H54*-H34 -> -827133.48 | I55: =I54*-I34 -> -933428.97 | J55: =J54*-J34 -> -1044050.3 | K55: =K54*-K34 -> -1157340.9
A57: X | B57: CHANGE IN WORKING CAPITAL FORECAST
D59: =D45 -> 2023 | E59: =E45 -> 2024 | F59: =F45 -> 2025 | G59: =G45 -> 2026 | H59: =H45 -> 2027 | I59: =I45 -> 2028 | J59: =J45 -> 2029 | K59: =K45 -> 2030
B61: ΔNWC (% Revenue) | D61: =SUM(Statements!F35:F39)/Statements!F5 -> -0.0034441472 | E61: =SUM(Statements!G35:G39)/Statements!G5 -> -0.00084805592 | F61: =SUM(Statements!H35:H39)/Statements!H5 -> -0.010097152 | G61: =AVERAGE($D$61:$F$61) -> -0.0047964518 | H61: =AVERAGE($D$61:$F$61) -> -0.0047964518 | I61: =AVERAGE($D$61:$F$61) -> -0.0047964518 | J61: =AVERAGE($D$61:$F$61) -> -0.0047964518 | K61: =AVERAGE($D$61:$F$61) -> -0.0047964518
...

Sheet Statements
A1: Netflix
A3: X | B3: INCOME STATEMENT (in thousands)
F4: 2023 | G4: =F4+1 -> 2024 | H4: =G4+1 -> 2025
B5: Revenues | F5: 33723297 | G5: 39000966 | H5: 45183036
B6: Cost of revenues | F6: 19715368 | G6: 21038464 | H6: 23275329
B7: Marketing | F7: 2657883 | G7: 2917554 | H7: 3301306
B8: Technology and development | F8: 2675758 | G8: 2925295 | H8: 3391390
B9: General and administrative | F9: 1720285 | G9: 1702039 | H9: 1888408
B10: Operating income (EBIT) | F10: 6954003 | G10: 10417614 | H10: 13326603
B11: Other income (expense):
B12: Interest expense | F12: -699826 | G12: -718733 | H12: -776510
B13: Interest and other income (expense) | F13: -48772 | G13: 266776 | H13: 172459
B14: Income before income taxes (EBT) | F14: 6205405 | G14: 9965657 | H14: 12722552
B15: Provision for income taxes | F15: -797415 | G15: -1254026 | H15: -1741351
B16: Net income | F16: 5407990 | G16: 8711631 | H16: 10981201
A19: X | B19: CASH FLOW STATEMENT (in thousands)
F20: 2023 | G20: =F20+1 -> 2024 | H20: =G20+1 -> 2025
B21: Cash flows from operating activities:
B22: Net income | F22: 5407990 | G22: 8711631 | H22: 10981201
B23: Adjustments to reconcile net income to net cash provided by
B24: operating activities:
B25: Additions to content assets | F25: -12554703 | G25: -16223617 | H25: -17096617
B26: Change in content liabilities | F26: -585602 | G26: -779135 | H26: -610838
B27: Amortization of content assets | F27: 14197437 | G27: 15301517 | H27: 16422166
B28: Depreciation and amortization of property, equipment and
B29: intangibles | F29: 356947 | G29: 328914 | H29: 333389
B30: Stock-based compensation expense | F30: 339368 | G30: 272588 | H30: 368449
B31: Foreign currency remeasurement loss (gain) on debt | F31: 176296 | G31: -121539 | H31: 72348
B32: Other non-cash items | F32: 512075 | G32: 494778 | H32: 577451
B33: Deferred income taxes | F33: -459359 | G33: -590698 | H33: -442056
B34: Changes in operating assets and liabilities:
B35: Other current assets | F35: -181003 | G35: 22180 | H35: -790661
B36: Accounts payable | F36: 93502 | G36: 121353 | H36: -8039
B37: Accrued expenses and other liabilities | F37: 103565 | G37: 191899 | H37: 881218
B38: Deferred revenue | F38: 178708 | G38: 77844 | H38: 254917
B39: Other non-current assets and liabilities | F39: -310920 | G39: -446351 | H39: -793655
B40: Net cash provided by operating activities | F40: 7274301 | G40: 7361364 | H40: 10149273
B42: Cash flows from investing activities:
B43: Purchases of property and equipment | F43: -348552 | G43: -439538 | H43: -688220
B44: Acquisitions | F44: 0 | G44: 0 | H44: -17194
...
